2022-09-30 10:10:18 :: INFO :: __init__ - [1] - sample-logger.create_app(__init__.py:30): logger connected!!
2022-09-30 10:10:18 :: INFO :: server - [1] - uvicorn.error.serve(server.py:75): Started server process [1]
2022-09-30 10:10:18 :: INFO :: on - [1] - uvicorn.error.startup(on.py:47): Waiting for application startup.
2022-09-30 10:10:18 :: INFO :: base - [1] - sqlalchemy.engine.Engine._execute_context(base.py:1853): select pg_catalog.version()
2022-09-30 10:10:18 :: INFO :: base - [1] - sqlalchemy.engine.Engine._execute_context(base.py:1858): [raw sql] {}
2022-09-30 10:10:18 :: INFO :: base - [1] - sqlalchemy.engine.Engine._execute_context(base.py:1853): select current_schema()
2022-09-30 10:10:18 :: INFO :: base - [1] - sqlalchemy.engine.Engine._execute_context(base.py:1858): [raw sql] {}
2022-09-30 10:10:18 :: INFO :: base - [1] - sqlalchemy.engine.Engine._execute_context(base.py:1853): show standard_conforming_strings
2022-09-30 10:10:18 :: INFO :: base - [1] - sqlalchemy.engine.Engine._execute_context(base.py:1858): [raw sql] {}
2022-09-30 10:10:18 :: INFO :: __init__ - [1] - sample-logger.__db_start(__init__.py:39): DB Connect!!
2022-09-30 10:10:18 :: INFO :: on - [1] - uvicorn.error.startup(on.py:61): Application startup complete.
2022-09-30 10:10:18 :: INFO :: server - [1] - uvicorn.error._log_started_message(server.py:207): Uvicorn running on http://0.0.0.0:5000 (Press CTRL+C to quit)
2022-09-30 10:11:07 :: INFO :: base - [1] - sqlalchemy.engine.Engine._begin_impl(base.py:1027): BEGIN (implicit)
2022-09-30 10:11:07 :: INFO :: base - [1] - sqlalchemy.engine.Engine._execute_context(base.py:1853): SELECT sample.id AS sample_id, sample.name AS sample_name 
FROM sample ORDER BY sample.id
2022-09-30 10:11:07 :: INFO :: base - [1] - sqlalchemy.engine.Engine._execute_context(base.py:1858): [generated in 0.00107s] {}
2022-09-30 10:11:07 :: ERROR :: httptools_impl - [1] - uvicorn.error.run_asgi(httptools_impl.py:409): Exception in ASGI application
Traceback (most recent call last):
  File "/usr/local/lib/python3.9/site-packages/uvicorn/protocols/http/httptools_impl.py", line 404, in run_asgi
    result = await app(  # type: ignore[func-returns-value]
  File "/usr/local/lib/python3.9/site-packages/uvicorn/middleware/proxy_headers.py", line 78, in __call__
    return await self.app(scope, receive, send)
  File "/usr/local/lib/python3.9/site-packages/fastapi/applications.py", line 270, in __call__
    await super().__call__(scope, receive, send)
  File "/usr/local/lib/python3.9/site-packages/starlette/applications.py", line 124, in __call__
    await self.middleware_stack(scope, receive, send)
  File "/usr/local/lib/python3.9/site-packages/starlette/middleware/errors.py", line 184, in __call__
    raise exc
  File "/usr/local/lib/python3.9/site-packages/starlette/middleware/errors.py", line 162, in __call__
    await self.app(scope, receive, _send)
  File "/usr/local/lib/python3.9/site-packages/starlette/middleware/exceptions.py", line 75, in __call__
    raise exc
  File "/usr/local/lib/python3.9/site-packages/starlette/middleware/exceptions.py", line 64, in __call__
    await self.app(scope, receive, sender)
  File "/usr/local/lib/python3.9/site-packages/fastapi/middleware/asyncexitstack.py", line 21, in __call__
    raise e
  File "/usr/local/lib/python3.9/site-packages/fastapi/middleware/asyncexitstack.py", line 18, in __call__
    await self.app(scope, receive, send)
  File "/usr/local/lib/python3.9/site-packages/starlette/routing.py", line 680, in __call__
    await route.handle(scope, receive, send)
  File "/usr/local/lib/python3.9/site-packages/starlette/routing.py", line 275, in handle
    await self.app(scope, receive, send)
  File "/usr/local/lib/python3.9/site-packages/starlette/routing.py", line 65, in app
    response = await func(request)
  File "/usr/local/lib/python3.9/site-packages/fastapi/routing.py", line 231, in app
    raw_response = await run_endpoint_function(
  File "/usr/local/lib/python3.9/site-packages/fastapi/routing.py", line 160, in run_endpoint_function
    return await dependant.call(**values)
  File "/app/app/routers/v1/base.py", line 10, in base
    return BaseReponse(BaseService().select())
  File "/app/app/services/base.py", line 13, in select
    return JSONResponse(status_code=200, content=dict(qry_result[0].__repr__()))
IndexError: list index out of range
2022-09-30 10:12:39 :: INFO :: base - [1] - sqlalchemy.engine.Engine._begin_impl(base.py:1027): BEGIN (implicit)
2022-09-30 10:12:39 :: INFO :: base - [1] - sqlalchemy.engine.Engine._execute_context(base.py:1853): SELECT sample.id AS sample_id, sample.name AS sample_name 
FROM sample ORDER BY sample.id
2022-09-30 10:12:39 :: INFO :: base - [1] - sqlalchemy.engine.Engine._execute_context(base.py:1858): [cached since 91.62s ago] {}
2022-09-30 10:12:39 :: ERROR :: httptools_impl - [1] - uvicorn.error.run_asgi(httptools_impl.py:409): Exception in ASGI application
Traceback (most recent call last):
  File "/usr/local/lib/python3.9/site-packages/uvicorn/protocols/http/httptools_impl.py", line 404, in run_asgi
    result = await app(  # type: ignore[func-returns-value]
  File "/usr/local/lib/python3.9/site-packages/uvicorn/middleware/proxy_headers.py", line 78, in __call__
    return await self.app(scope, receive, send)
  File "/usr/local/lib/python3.9/site-packages/fastapi/applications.py", line 270, in __call__
    await super().__call__(scope, receive, send)
  File "/usr/local/lib/python3.9/site-packages/starlette/applications.py", line 124, in __call__
    await self.middleware_stack(scope, receive, send)
  File "/usr/local/lib/python3.9/site-packages/starlette/middleware/errors.py", line 184, in __call__
    raise exc
  File "/usr/local/lib/python3.9/site-packages/starlette/middleware/errors.py", line 162, in __call__
    await self.app(scope, receive, _send)
  File "/usr/local/lib/python3.9/site-packages/starlette/middleware/exceptions.py", line 75, in __call__
    raise exc
  File "/usr/local/lib/python3.9/site-packages/starlette/middleware/exceptions.py", line 64, in __call__
    await self.app(scope, receive, sender)
  File "/usr/local/lib/python3.9/site-packages/fastapi/middleware/asyncexitstack.py", line 21, in __call__
    raise e
  File "/usr/local/lib/python3.9/site-packages/fastapi/middleware/asyncexitstack.py", line 18, in __call__
    await self.app(scope, receive, send)
  File "/usr/local/lib/python3.9/site-packages/starlette/routing.py", line 680, in __call__
    await route.handle(scope, receive, send)
  File "/usr/local/lib/python3.9/site-packages/starlette/routing.py", line 275, in handle
    await self.app(scope, receive, send)
  File "/usr/local/lib/python3.9/site-packages/starlette/routing.py", line 65, in app
    response = await func(request)
  File "/usr/local/lib/python3.9/site-packages/fastapi/routing.py", line 231, in app
    raw_response = await run_endpoint_function(
  File "/usr/local/lib/python3.9/site-packages/fastapi/routing.py", line 160, in run_endpoint_function
    return await dependant.call(**values)
  File "/app/app/routers/v1/base.py", line 10, in base
    return BaseReponse(BaseService().select())
  File "/app/app/services/base.py", line 13, in select
    return JSONResponse(status_code=200, content=dict(qry_result[0].__repr__()))
ValueError: dictionary update sequence element #0 has length 1; 2 is required
2022-09-30 10:13:22 :: INFO :: __init__ - [1] - sample-logger.create_app(__init__.py:30): logger connected!!
2022-09-30 10:13:22 :: INFO :: server - [1] - uvicorn.error.serve(server.py:75): Started server process [1]
2022-09-30 10:13:22 :: INFO :: on - [1] - uvicorn.error.startup(on.py:47): Waiting for application startup.
2022-09-30 10:13:22 :: INFO :: base - [1] - sqlalchemy.engine.Engine._execute_context(base.py:1853): select pg_catalog.version()
2022-09-30 10:13:22 :: INFO :: base - [1] - sqlalchemy.engine.Engine._execute_context(base.py:1858): [raw sql] {}
2022-09-30 10:13:22 :: INFO :: base - [1] - sqlalchemy.engine.Engine._execute_context(base.py:1853): select current_schema()
2022-09-30 10:13:22 :: INFO :: base - [1] - sqlalchemy.engine.Engine._execute_context(base.py:1858): [raw sql] {}
2022-09-30 10:13:22 :: INFO :: base - [1] - sqlalchemy.engine.Engine._execute_context(base.py:1853): show standard_conforming_strings
2022-09-30 10:13:22 :: INFO :: base - [1] - sqlalchemy.engine.Engine._execute_context(base.py:1858): [raw sql] {}
2022-09-30 10:13:22 :: INFO :: __init__ - [1] - sample-logger.__db_start(__init__.py:39): DB Connect!!
2022-09-30 10:13:22 :: INFO :: on - [1] - uvicorn.error.startup(on.py:61): Application startup complete.
2022-09-30 10:13:22 :: INFO :: server - [1] - uvicorn.error._log_started_message(server.py:207): Uvicorn running on http://0.0.0.0:5000 (Press CTRL+C to quit)
2022-09-30 10:13:26 :: INFO :: base - [1] - sqlalchemy.engine.Engine._begin_impl(base.py:1027): BEGIN (implicit)
2022-09-30 10:13:26 :: INFO :: base - [1] - sqlalchemy.engine.Engine._execute_context(base.py:1853): SELECT sample.id AS sample_id, sample.name AS sample_name 
FROM sample ORDER BY sample.id
2022-09-30 10:13:26 :: INFO :: base - [1] - sqlalchemy.engine.Engine._execute_context(base.py:1858): [generated in 0.00114s] {}
2022-09-30 10:13:26 :: INFO :: base - [1] - sqlalchemy.engine.Engine._rollback_impl(base.py:1055): ROLLBACK
2022-09-30 10:13:26 :: ERROR :: httptools_impl - [1] - uvicorn.error.run_asgi(httptools_impl.py:409): Exception in ASGI application
Traceback (most recent call last):
  File "/usr/local/lib/python3.9/site-packages/uvicorn/protocols/http/httptools_impl.py", line 404, in run_asgi
    result = await app(  # type: ignore[func-returns-value]
  File "/usr/local/lib/python3.9/site-packages/uvicorn/middleware/proxy_headers.py", line 78, in __call__
    return await self.app(scope, receive, send)
  File "/usr/local/lib/python3.9/site-packages/fastapi/applications.py", line 270, in __call__
    await super().__call__(scope, receive, send)
  File "/usr/local/lib/python3.9/site-packages/starlette/applications.py", line 124, in __call__
    await self.middleware_stack(scope, receive, send)
  File "/usr/local/lib/python3.9/site-packages/starlette/middleware/errors.py", line 184, in __call__
    raise exc
  File "/usr/local/lib/python3.9/site-packages/starlette/middleware/errors.py", line 162, in __call__
    await self.app(scope, receive, _send)
  File "/usr/local/lib/python3.9/site-packages/starlette/middleware/exceptions.py", line 75, in __call__
    raise exc
  File "/usr/local/lib/python3.9/site-packages/starlette/middleware/exceptions.py", line 64, in __call__
    await self.app(scope, receive, sender)
  File "/usr/local/lib/python3.9/site-packages/fastapi/middleware/asyncexitstack.py", line 21, in __call__
    raise e
  File "/usr/local/lib/python3.9/site-packages/fastapi/middleware/asyncexitstack.py", line 18, in __call__
    await self.app(scope, receive, send)
  File "/usr/local/lib/python3.9/site-packages/starlette/routing.py", line 680, in __call__
    await route.handle(scope, receive, send)
  File "/usr/local/lib/python3.9/site-packages/starlette/routing.py", line 275, in handle
    await self.app(scope, receive, send)
  File "/usr/local/lib/python3.9/site-packages/starlette/routing.py", line 65, in app
    response = await func(request)
  File "/usr/local/lib/python3.9/site-packages/fastapi/routing.py", line 231, in app
    raw_response = await run_endpoint_function(
  File "/usr/local/lib/python3.9/site-packages/fastapi/routing.py", line 160, in run_endpoint_function
    return await dependant.call(**values)
  File "/app/app/routers/v1/base.py", line 10, in base
    return BaseReponse(BaseService().select())
  File "pydantic/main.py", line 333, in pydantic.main.BaseModel.__init__
TypeError: __init__() takes exactly 1 positional argument (2 given)
2022-09-30 10:19:24 :: INFO :: __init__ - [1] - sample-logger.create_app(__init__.py:30): logger connected!!
2022-09-30 10:19:24 :: INFO :: server - [1] - uvicorn.error.serve(server.py:75): Started server process [1]
2022-09-30 10:19:24 :: INFO :: on - [1] - uvicorn.error.startup(on.py:47): Waiting for application startup.
2022-09-30 10:19:24 :: INFO :: base - [1] - sqlalchemy.engine.Engine._execute_context(base.py:1853): select pg_catalog.version()
2022-09-30 10:19:24 :: INFO :: base - [1] - sqlalchemy.engine.Engine._execute_context(base.py:1858): [raw sql] {}
2022-09-30 10:19:24 :: INFO :: base - [1] - sqlalchemy.engine.Engine._execute_context(base.py:1853): select current_schema()
2022-09-30 10:19:24 :: INFO :: base - [1] - sqlalchemy.engine.Engine._execute_context(base.py:1858): [raw sql] {}
2022-09-30 10:19:24 :: INFO :: base - [1] - sqlalchemy.engine.Engine._execute_context(base.py:1853): show standard_conforming_strings
2022-09-30 10:19:24 :: INFO :: base - [1] - sqlalchemy.engine.Engine._execute_context(base.py:1858): [raw sql] {}
2022-09-30 10:19:24 :: INFO :: __init__ - [1] - sample-logger.__db_start(__init__.py:39): DB Connect!!
2022-09-30 10:19:24 :: INFO :: on - [1] - uvicorn.error.startup(on.py:61): Application startup complete.
2022-09-30 10:19:24 :: INFO :: server - [1] - uvicorn.error._log_started_message(server.py:207): Uvicorn running on http://0.0.0.0:5000 (Press CTRL+C to quit)
2022-09-30 10:19:42 :: INFO :: base - [1] - sqlalchemy.engine.Engine._begin_impl(base.py:1027): BEGIN (implicit)
2022-09-30 10:19:42 :: INFO :: base - [1] - sqlalchemy.engine.Engine._execute_context(base.py:1853): SELECT sample.id AS sample_id, sample.name AS sample_name 
FROM sample ORDER BY sample.id
2022-09-30 10:19:42 :: INFO :: base - [1] - sqlalchemy.engine.Engine._execute_context(base.py:1858): [generated in 0.00172s] {}
2022-09-30 10:19:42 :: INFO :: base - [1] - sqlalchemy.engine.Engine._rollback_impl(base.py:1055): ROLLBACK
2022-09-30 10:19:42 :: ERROR :: httptools_impl - [1] - uvicorn.error.run_asgi(httptools_impl.py:409): Exception in ASGI application
Traceback (most recent call last):
  File "/usr/local/lib/python3.9/site-packages/uvicorn/protocols/http/httptools_impl.py", line 404, in run_asgi
    result = await app(  # type: ignore[func-returns-value]
  File "/usr/local/lib/python3.9/site-packages/uvicorn/middleware/proxy_headers.py", line 78, in __call__
    return await self.app(scope, receive, send)
  File "/usr/local/lib/python3.9/site-packages/fastapi/applications.py", line 270, in __call__
    await super().__call__(scope, receive, send)
  File "/usr/local/lib/python3.9/site-packages/starlette/applications.py", line 124, in __call__
    await self.middleware_stack(scope, receive, send)
  File "/usr/local/lib/python3.9/site-packages/starlette/middleware/errors.py", line 184, in __call__
    raise exc
  File "/usr/local/lib/python3.9/site-packages/starlette/middleware/errors.py", line 162, in __call__
    await self.app(scope, receive, _send)
  File "/usr/local/lib/python3.9/site-packages/starlette/middleware/exceptions.py", line 75, in __call__
    raise exc
  File "/usr/local/lib/python3.9/site-packages/starlette/middleware/exceptions.py", line 64, in __call__
    await self.app(scope, receive, sender)
  File "/usr/local/lib/python3.9/site-packages/fastapi/middleware/asyncexitstack.py", line 21, in __call__
    raise e
  File "/usr/local/lib/python3.9/site-packages/fastapi/middleware/asyncexitstack.py", line 18, in __call__
    await self.app(scope, receive, send)
  File "/usr/local/lib/python3.9/site-packages/starlette/routing.py", line 680, in __call__
    await route.handle(scope, receive, send)
  File "/usr/local/lib/python3.9/site-packages/starlette/routing.py", line 275, in handle
    await self.app(scope, receive, send)
  File "/usr/local/lib/python3.9/site-packages/starlette/routing.py", line 65, in app
    response = await func(request)
  File "/usr/local/lib/python3.9/site-packages/fastapi/routing.py", line 231, in app
    raw_response = await run_endpoint_function(
  File "/usr/local/lib/python3.9/site-packages/fastapi/routing.py", line 160, in run_endpoint_function
    return await dependant.call(**values)
  File "/app/app/routers/v1/base.py", line 10, in base
    return Response(status_code=200, body=BaseService().select())
TypeError: __init__() got an unexpected keyword argument 'body'
2022-09-30 10:20:22 :: INFO :: __init__ - [1] - sample-logger.create_app(__init__.py:30): logger connected!!
2022-09-30 10:20:22 :: INFO :: server - [1] - uvicorn.error.serve(server.py:75): Started server process [1]
2022-09-30 10:20:22 :: INFO :: on - [1] - uvicorn.error.startup(on.py:47): Waiting for application startup.
2022-09-30 10:20:22 :: INFO :: base - [1] - sqlalchemy.engine.Engine._execute_context(base.py:1853): select pg_catalog.version()
2022-09-30 10:20:22 :: INFO :: base - [1] - sqlalchemy.engine.Engine._execute_context(base.py:1858): [raw sql] {}
2022-09-30 10:20:22 :: INFO :: base - [1] - sqlalchemy.engine.Engine._execute_context(base.py:1853): select current_schema()
2022-09-30 10:20:22 :: INFO :: base - [1] - sqlalchemy.engine.Engine._execute_context(base.py:1858): [raw sql] {}
2022-09-30 10:20:22 :: INFO :: base - [1] - sqlalchemy.engine.Engine._execute_context(base.py:1853): show standard_conforming_strings
2022-09-30 10:20:22 :: INFO :: base - [1] - sqlalchemy.engine.Engine._execute_context(base.py:1858): [raw sql] {}
2022-09-30 10:20:22 :: INFO :: __init__ - [1] - sample-logger.__db_start(__init__.py:39): DB Connect!!
2022-09-30 10:20:22 :: INFO :: on - [1] - uvicorn.error.startup(on.py:61): Application startup complete.
2022-09-30 10:20:22 :: INFO :: server - [1] - uvicorn.error._log_started_message(server.py:207): Uvicorn running on http://0.0.0.0:5000 (Press CTRL+C to quit)
2022-09-30 10:20:23 :: INFO :: base - [1] - sqlalchemy.engine.Engine._begin_impl(base.py:1027): BEGIN (implicit)
2022-09-30 10:20:23 :: INFO :: base - [1] - sqlalchemy.engine.Engine._execute_context(base.py:1853): SELECT sample.id AS sample_id, sample.name AS sample_name 
FROM sample ORDER BY sample.id
2022-09-30 10:20:23 :: INFO :: base - [1] - sqlalchemy.engine.Engine._execute_context(base.py:1858): [generated in 0.00080s] {}
2022-09-30 10:20:23 :: INFO :: base - [1] - sqlalchemy.engine.Engine._rollback_impl(base.py:1055): ROLLBACK
2022-09-30 10:20:23 :: ERROR :: httptools_impl - [1] - uvicorn.error.run_asgi(httptools_impl.py:409): Exception in ASGI application
Traceback (most recent call last):
  File "/usr/local/lib/python3.9/site-packages/uvicorn/protocols/http/httptools_impl.py", line 404, in run_asgi
    result = await app(  # type: ignore[func-returns-value]
  File "/usr/local/lib/python3.9/site-packages/uvicorn/middleware/proxy_headers.py", line 78, in __call__
    return await self.app(scope, receive, send)
  File "/usr/local/lib/python3.9/site-packages/fastapi/applications.py", line 270, in __call__
    await super().__call__(scope, receive, send)
  File "/usr/local/lib/python3.9/site-packages/starlette/applications.py", line 124, in __call__
    await self.middleware_stack(scope, receive, send)
  File "/usr/local/lib/python3.9/site-packages/starlette/middleware/errors.py", line 184, in __call__
    raise exc
  File "/usr/local/lib/python3.9/site-packages/starlette/middleware/errors.py", line 162, in __call__
    await self.app(scope, receive, _send)
  File "/usr/local/lib/python3.9/site-packages/starlette/middleware/exceptions.py", line 75, in __call__
    raise exc
  File "/usr/local/lib/python3.9/site-packages/starlette/middleware/exceptions.py", line 64, in __call__
    await self.app(scope, receive, sender)
  File "/usr/local/lib/python3.9/site-packages/fastapi/middleware/asyncexitstack.py", line 21, in __call__
    raise e
  File "/usr/local/lib/python3.9/site-packages/fastapi/middleware/asyncexitstack.py", line 18, in __call__
    await self.app(scope, receive, send)
  File "/usr/local/lib/python3.9/site-packages/starlette/routing.py", line 680, in __call__
    await route.handle(scope, receive, send)
  File "/usr/local/lib/python3.9/site-packages/starlette/routing.py", line 275, in handle
    await self.app(scope, receive, send)
  File "/usr/local/lib/python3.9/site-packages/starlette/routing.py", line 65, in app
    response = await func(request)
  File "/usr/local/lib/python3.9/site-packages/fastapi/routing.py", line 231, in app
    raw_response = await run_endpoint_function(
  File "/usr/local/lib/python3.9/site-packages/fastapi/routing.py", line 160, in run_endpoint_function
    return await dependant.call(**values)
  File "/app/app/routers/v1/base.py", line 10, in base
    return Response(status_code=200, content=BaseService().select())
  File "/usr/local/lib/python3.9/site-packages/starlette/responses.py", line 54, in __init__
    self.body = self.render(content)
  File "/usr/local/lib/python3.9/site-packages/starlette/responses.py", line 62, in render
    return content.encode(self.charset)
AttributeError: 'list' object has no attribute 'encode'
2022-09-30 10:23:08 :: INFO :: __init__ - [1] - sample-logger.create_app(__init__.py:30): logger connected!!
2022-09-30 10:23:08 :: INFO :: server - [1] - uvicorn.error.serve(server.py:75): Started server process [1]
2022-09-30 10:23:08 :: INFO :: on - [1] - uvicorn.error.startup(on.py:47): Waiting for application startup.
2022-09-30 10:23:08 :: INFO :: base - [1] - sqlalchemy.engine.Engine._execute_context(base.py:1853): select pg_catalog.version()
2022-09-30 10:23:08 :: INFO :: base - [1] - sqlalchemy.engine.Engine._execute_context(base.py:1858): [raw sql] {}
2022-09-30 10:23:08 :: INFO :: base - [1] - sqlalchemy.engine.Engine._execute_context(base.py:1853): select current_schema()
2022-09-30 10:23:08 :: INFO :: base - [1] - sqlalchemy.engine.Engine._execute_context(base.py:1858): [raw sql] {}
2022-09-30 10:23:08 :: INFO :: base - [1] - sqlalchemy.engine.Engine._execute_context(base.py:1853): show standard_conforming_strings
2022-09-30 10:23:08 :: INFO :: base - [1] - sqlalchemy.engine.Engine._execute_context(base.py:1858): [raw sql] {}
2022-09-30 10:23:08 :: INFO :: __init__ - [1] - sample-logger.__db_start(__init__.py:39): DB Connect!!
2022-09-30 10:23:08 :: INFO :: on - [1] - uvicorn.error.startup(on.py:61): Application startup complete.
2022-09-30 10:23:08 :: INFO :: server - [1] - uvicorn.error._log_started_message(server.py:207): Uvicorn running on http://0.0.0.0:5000 (Press CTRL+C to quit)
2022-09-30 10:23:10 :: INFO :: base - [1] - sqlalchemy.engine.Engine._begin_impl(base.py:1027): BEGIN (implicit)
2022-09-30 10:23:10 :: INFO :: base - [1] - sqlalchemy.engine.Engine._execute_context(base.py:1853): SELECT sample.id AS sample_id, sample.name AS sample_name 
FROM sample ORDER BY sample.id
2022-09-30 10:23:10 :: INFO :: base - [1] - sqlalchemy.engine.Engine._execute_context(base.py:1858): [generated in 0.00096s] {}
2022-09-30 10:23:10 :: INFO :: base - [1] - sqlalchemy.engine.Engine._rollback_impl(base.py:1055): ROLLBACK
2022-09-30 10:23:10 :: ERROR :: httptools_impl - [1] - uvicorn.error.run_asgi(httptools_impl.py:409): Exception in ASGI application
Traceback (most recent call last):
  File "/usr/local/lib/python3.9/site-packages/uvicorn/protocols/http/httptools_impl.py", line 404, in run_asgi
    result = await app(  # type: ignore[func-returns-value]
  File "/usr/local/lib/python3.9/site-packages/uvicorn/middleware/proxy_headers.py", line 78, in __call__
    return await self.app(scope, receive, send)
  File "/usr/local/lib/python3.9/site-packages/fastapi/applications.py", line 270, in __call__
    await super().__call__(scope, receive, send)
  File "/usr/local/lib/python3.9/site-packages/starlette/applications.py", line 124, in __call__
    await self.middleware_stack(scope, receive, send)
  File "/usr/local/lib/python3.9/site-packages/starlette/middleware/errors.py", line 184, in __call__
    raise exc
  File "/usr/local/lib/python3.9/site-packages/starlette/middleware/errors.py", line 162, in __call__
    await self.app(scope, receive, _send)
  File "/usr/local/lib/python3.9/site-packages/starlette/middleware/exceptions.py", line 75, in __call__
    raise exc
  File "/usr/local/lib/python3.9/site-packages/starlette/middleware/exceptions.py", line 64, in __call__
    await self.app(scope, receive, sender)
  File "/usr/local/lib/python3.9/site-packages/fastapi/middleware/asyncexitstack.py", line 21, in __call__
    raise e
  File "/usr/local/lib/python3.9/site-packages/fastapi/middleware/asyncexitstack.py", line 18, in __call__
    await self.app(scope, receive, send)
  File "/usr/local/lib/python3.9/site-packages/starlette/routing.py", line 680, in __call__
    await route.handle(scope, receive, send)
  File "/usr/local/lib/python3.9/site-packages/starlette/routing.py", line 275, in handle
    await self.app(scope, receive, send)
  File "/usr/local/lib/python3.9/site-packages/starlette/routing.py", line 65, in app
    response = await func(request)
  File "/usr/local/lib/python3.9/site-packages/fastapi/routing.py", line 231, in app
    raw_response = await run_endpoint_function(
  File "/usr/local/lib/python3.9/site-packages/fastapi/routing.py", line 160, in run_endpoint_function
    return await dependant.call(**values)
  File "/app/app/routers/v1/base.py", line 10, in base
    return Response(status_code=200, content=BaseService().select()[0])
  File "/usr/local/lib/python3.9/site-packages/starlette/responses.py", line 54, in __init__
    self.body = self.render(content)
  File "/usr/local/lib/python3.9/site-packages/starlette/responses.py", line 62, in render
    return content.encode(self.charset)
AttributeError: 'Sample' object has no attribute 'encode'
2022-09-30 10:23:48 :: INFO :: __init__ - [1] - sample-logger.create_app(__init__.py:30): logger connected!!
2022-09-30 10:23:48 :: INFO :: server - [1] - uvicorn.error.serve(server.py:75): Started server process [1]
2022-09-30 10:23:48 :: INFO :: on - [1] - uvicorn.error.startup(on.py:47): Waiting for application startup.
2022-09-30 10:23:48 :: INFO :: base - [1] - sqlalchemy.engine.Engine._execute_context(base.py:1853): select pg_catalog.version()
2022-09-30 10:23:48 :: INFO :: base - [1] - sqlalchemy.engine.Engine._execute_context(base.py:1858): [raw sql] {}
2022-09-30 10:23:48 :: INFO :: base - [1] - sqlalchemy.engine.Engine._execute_context(base.py:1853): select current_schema()
2022-09-30 10:23:48 :: INFO :: base - [1] - sqlalchemy.engine.Engine._execute_context(base.py:1858): [raw sql] {}
2022-09-30 10:23:48 :: INFO :: base - [1] - sqlalchemy.engine.Engine._execute_context(base.py:1853): show standard_conforming_strings
2022-09-30 10:23:48 :: INFO :: base - [1] - sqlalchemy.engine.Engine._execute_context(base.py:1858): [raw sql] {}
2022-09-30 10:23:48 :: INFO :: __init__ - [1] - sample-logger.__db_start(__init__.py:39): DB Connect!!
2022-09-30 10:23:48 :: INFO :: on - [1] - uvicorn.error.startup(on.py:61): Application startup complete.
2022-09-30 10:23:48 :: INFO :: server - [1] - uvicorn.error._log_started_message(server.py:207): Uvicorn running on http://0.0.0.0:5000 (Press CTRL+C to quit)
2022-09-30 10:23:50 :: INFO :: base - [1] - sqlalchemy.engine.Engine._begin_impl(base.py:1027): BEGIN (implicit)
2022-09-30 10:23:50 :: INFO :: base - [1] - sqlalchemy.engine.Engine._execute_context(base.py:1853): SELECT sample.id AS sample_id, sample.name AS sample_name 
FROM sample ORDER BY sample.id
2022-09-30 10:23:50 :: INFO :: base - [1] - sqlalchemy.engine.Engine._execute_context(base.py:1858): [generated in 0.00221s] {}
2022-09-30 10:23:50 :: INFO :: base - [1] - sqlalchemy.engine.Engine._rollback_impl(base.py:1055): ROLLBACK
2022-09-30 10:24:15 :: INFO :: __init__ - [1] - sample-logger.create_app(__init__.py:30): logger connected!!
2022-09-30 10:24:15 :: INFO :: server - [1] - uvicorn.error.serve(server.py:75): Started server process [1]
2022-09-30 10:24:15 :: INFO :: on - [1] - uvicorn.error.startup(on.py:47): Waiting for application startup.
2022-09-30 10:24:15 :: INFO :: base - [1] - sqlalchemy.engine.Engine._execute_context(base.py:1853): select pg_catalog.version()
2022-09-30 10:24:15 :: INFO :: base - [1] - sqlalchemy.engine.Engine._execute_context(base.py:1858): [raw sql] {}
2022-09-30 10:24:15 :: INFO :: base - [1] - sqlalchemy.engine.Engine._execute_context(base.py:1853): select current_schema()
2022-09-30 10:24:15 :: INFO :: base - [1] - sqlalchemy.engine.Engine._execute_context(base.py:1858): [raw sql] {}
2022-09-30 10:24:15 :: INFO :: base - [1] - sqlalchemy.engine.Engine._execute_context(base.py:1853): show standard_conforming_strings
2022-09-30 10:24:15 :: INFO :: base - [1] - sqlalchemy.engine.Engine._execute_context(base.py:1858): [raw sql] {}
2022-09-30 10:24:15 :: INFO :: __init__ - [1] - sample-logger.__db_start(__init__.py:39): DB Connect!!
2022-09-30 10:24:15 :: INFO :: on - [1] - uvicorn.error.startup(on.py:61): Application startup complete.
2022-09-30 10:24:15 :: INFO :: server - [1] - uvicorn.error._log_started_message(server.py:207): Uvicorn running on http://0.0.0.0:5000 (Press CTRL+C to quit)
2022-09-30 10:24:18 :: INFO :: base - [1] - sqlalchemy.engine.Engine._begin_impl(base.py:1027): BEGIN (implicit)
2022-09-30 10:24:18 :: INFO :: base - [1] - sqlalchemy.engine.Engine._execute_context(base.py:1853): SELECT sample.id AS sample_id, sample.name AS sample_name 
FROM sample ORDER BY sample.id
2022-09-30 10:24:18 :: INFO :: base - [1] - sqlalchemy.engine.Engine._execute_context(base.py:1858): [generated in 0.00159s] {}
2022-09-30 10:24:18 :: INFO :: base - [1] - sqlalchemy.engine.Engine._rollback_impl(base.py:1055): ROLLBACK
2022-09-30 10:25:56 :: INFO :: base - [1] - sqlalchemy.engine.Engine._begin_impl(base.py:1027): BEGIN (implicit)
2022-09-30 10:25:56 :: INFO :: base - [1] - sqlalchemy.engine.Engine._execute_context(base.py:1853): SELECT sample.id AS sample_id, sample.name AS sample_name 
FROM sample ORDER BY sample.id
2022-09-30 10:25:56 :: INFO :: base - [1] - sqlalchemy.engine.Engine._execute_context(base.py:1858): [cached since 98.18s ago] {}
2022-09-30 10:25:56 :: INFO :: base - [1] - sqlalchemy.engine.Engine._rollback_impl(base.py:1055): ROLLBACK
2022-09-30 10:27:24 :: INFO :: server - [1] - uvicorn.error.shutdown(server.py:253): Shutting down
2022-09-30 10:27:24 :: INFO :: on - [1] - uvicorn.error.shutdown(on.py:66): Waiting for application shutdown.
2022-09-30 10:27:24 :: INFO :: __init__ - [1] - sample-logger.__db_shutdown(__init__.py:49): DB Disconnect!!
2022-09-30 10:27:24 :: INFO :: on - [1] - uvicorn.error.shutdown(on.py:77): Application shutdown complete.
2022-09-30 10:27:24 :: INFO :: server - [1] - uvicorn.error.serve(server.py:85): Finished server process [1]
2022-09-30 10:31:27 :: INFO :: __init__ - [1] - sample-logger.create_app(__init__.py:30): logger connected!!
2022-09-30 10:31:27 :: INFO :: server - [1] - uvicorn.error.serve(server.py:75): Started server process [1]
2022-09-30 10:31:27 :: INFO :: on - [1] - uvicorn.error.startup(on.py:47): Waiting for application startup.
2022-09-30 10:31:27 :: ERROR :: __init__ - [1] - sample-logger.__db_start(__init__.py:41): DB Connect Error!!!
2022-09-30 10:31:27 :: ERROR :: __init__ - [1] - sample-logger.__db_start(__init__.py:42): (psycopg2.OperationalError) FATAL:  no pg_hba.conf entry for host "172.21.0.3", user "sample", database "sample", SSL off

(Background on this error at: https://sqlalche.me/e/14/e3q8)
2022-09-30 10:31:27 :: INFO :: on - [1] - uvicorn.error.startup(on.py:61): Application startup complete.
2022-09-30 10:31:27 :: INFO :: server - [1] - uvicorn.error._log_started_message(server.py:207): Uvicorn running on http://0.0.0.0:5000 (Press CTRL+C to quit)
2022-09-30 10:33:22 :: INFO :: base - [1] - sqlalchemy.engine.Engine._execute_context(base.py:1853): select pg_catalog.version()
2022-09-30 10:33:22 :: INFO :: base - [1] - sqlalchemy.engine.Engine._execute_context(base.py:1858): [raw sql] {}
2022-09-30 10:33:22 :: INFO :: base - [1] - sqlalchemy.engine.Engine._execute_context(base.py:1853): select current_schema()
2022-09-30 10:33:22 :: INFO :: base - [1] - sqlalchemy.engine.Engine._execute_context(base.py:1858): [raw sql] {}
2022-09-30 10:33:22 :: INFO :: base - [1] - sqlalchemy.engine.Engine._execute_context(base.py:1853): show standard_conforming_strings
2022-09-30 10:33:22 :: INFO :: base - [1] - sqlalchemy.engine.Engine._execute_context(base.py:1858): [raw sql] {}
2022-09-30 10:33:22 :: INFO :: base - [1] - sqlalchemy.engine.Engine._begin_impl(base.py:1027): BEGIN (implicit)
2022-09-30 10:33:22 :: INFO :: base - [1] - sqlalchemy.engine.Engine._execute_context(base.py:1853): SELECT sample.id AS sample_id, sample.name AS sample_name 
FROM sample ORDER BY sample.id
2022-09-30 10:33:22 :: INFO :: base - [1] - sqlalchemy.engine.Engine._execute_context(base.py:1858): [generated in 0.00075s] {}
2022-09-30 10:33:22 :: INFO :: base - [1] - sqlalchemy.engine.Engine._rollback_impl(base.py:1055): ROLLBACK
2022-09-30 10:41:25 :: INFO :: __init__ - [1] - sample-logger.create_app(__init__.py:30): logger connected!!
2022-09-30 10:41:25 :: INFO :: server - [1] - uvicorn.error.serve(server.py:75): Started server process [1]
2022-09-30 10:41:25 :: INFO :: on - [1] - uvicorn.error.startup(on.py:47): Waiting for application startup.
2022-09-30 10:41:25 :: INFO :: base - [1] - sqlalchemy.engine.Engine._execute_context(base.py:1853): select pg_catalog.version()
2022-09-30 10:41:25 :: INFO :: base - [1] - sqlalchemy.engine.Engine._execute_context(base.py:1858): [raw sql] {}
2022-09-30 10:41:25 :: INFO :: base - [1] - sqlalchemy.engine.Engine._execute_context(base.py:1853): select current_schema()
2022-09-30 10:41:25 :: INFO :: base - [1] - sqlalchemy.engine.Engine._execute_context(base.py:1858): [raw sql] {}
2022-09-30 10:41:25 :: INFO :: base - [1] - sqlalchemy.engine.Engine._execute_context(base.py:1853): show standard_conforming_strings
2022-09-30 10:41:25 :: INFO :: base - [1] - sqlalchemy.engine.Engine._execute_context(base.py:1858): [raw sql] {}
2022-09-30 10:41:25 :: INFO :: __init__ - [1] - sample-logger.__db_start(__init__.py:39): DB Connect!!
2022-09-30 10:41:25 :: INFO :: on - [1] - uvicorn.error.startup(on.py:61): Application startup complete.
2022-09-30 10:41:25 :: INFO :: server - [1] - uvicorn.error._log_started_message(server.py:207): Uvicorn running on http://0.0.0.0:5000 (Press CTRL+C to quit)
2022-09-30 10:41:27 :: INFO :: base - [1] - sqlalchemy.engine.Engine._begin_impl(base.py:1027): BEGIN (implicit)
2022-09-30 10:41:27 :: INFO :: base - [1] - sqlalchemy.engine.Engine._execute_context(base.py:1853): SELECT sample.id AS sample_id, sample.name AS sample_name 
FROM sample ORDER BY sample.id
2022-09-30 10:41:27 :: INFO :: base - [1] - sqlalchemy.engine.Engine._execute_context(base.py:1858): [generated in 0.00135s] {}
2022-09-30 10:41:27 :: INFO :: base - [1] - sqlalchemy.engine.Engine._rollback_impl(base.py:1055): ROLLBACK
2022-09-30 10:41:28 :: INFO :: base - [1] - sqlalchemy.engine.Engine._begin_impl(base.py:1027): BEGIN (implicit)
2022-09-30 10:41:28 :: INFO :: base - [1] - sqlalchemy.engine.Engine._execute_context(base.py:1853): SELECT sample.id AS sample_id, sample.name AS sample_name 
FROM sample ORDER BY sample.id
2022-09-30 10:41:28 :: INFO :: base - [1] - sqlalchemy.engine.Engine._execute_context(base.py:1858): [cached since 1.1s ago] {}
2022-09-30 10:41:28 :: INFO :: base - [1] - sqlalchemy.engine.Engine._rollback_impl(base.py:1055): ROLLBACK
